<?xml version="1.0" ?>
<!-- =================================================================================== -->
<!-- |    This document was autogenerated by xacro from xacro/orion.xacro              | -->
<!-- |    EDITING THIS FILE BY HAND IS NOT RECOMMENDED                                 | -->
<!-- =================================================================================== -->
<robot name="orion" xmlns:gz="http://gazebosim.org/schema">
  <!-- ── 1. MATERIALS ─────────────────────────────────────────────── -->
  <material name="grey">
    <color rgba="0.60 0.60 0.60 1.0"/>
  </material>
  <material name="dark_grey">
    <color rgba="0.25 0.25 0.25 1.0"/>
  </material>
  <material name="black">
    <color rgba="0.08 0.08 0.08 1.0"/>
  </material>
  <material name="white">
    <color rgba="0.90 0.90 0.90 1.0"/>
  </material>
  <material name="red">
    <color rgba="0.80 0.10 0.10 1.0"/>
  </material>
  <material name="blue">
    <color rgba="0.10 0.10 0.80 1.0"/>
  </material>
  <material name="green">
    <color rgba="0.10 0.70 0.10 1.0"/>
  </material>
  <material name="orange">
    <color rgba="1.00 0.45 0.00 1.0"/>
  </material>
  <material name="yellow">
    <color rgba="1.00 0.85 0.00 1.0"/>
  </material>
  <ros2_control name="OrionSystem" type="system">
    <hardware>
      <plugin>gz_ros2_control/GazeboSimSystem</plugin>
    </hardware>
    <!-- MECANUM DRIVE  (velocity commands)      -->
    <joint name="front_left_wheel_joint">
      <command_interface name="velocity">
        <param name="min">-10.0</param>
        <param name="max"> 10.0</param>
      </command_interface>
      <state_interface name="position"/>
      <state_interface name="velocity"/>
    </joint>
    <joint name="front_right_wheel_joint">
      <command_interface name="velocity">
        <param name="min">-10.0</param>
        <param name="max"> 10.0</param>
      </command_interface>
      <state_interface name="position"/>
      <state_interface name="velocity"/>
    </joint>
    <joint name="rear_left_wheel_joint">
      <command_interface name="velocity">
        <param name="min">-10.0</param>
        <param name="max"> 10.0</param>
      </command_interface>
      <state_interface name="position"/>
      <state_interface name="velocity"/>
    </joint>
    <joint name="rear_right_wheel_joint">
      <command_interface name="velocity">
        <param name="min">-10.0</param>
        <param name="max"> 10.0</param>
      </command_interface>
      <state_interface name="position"/>
      <state_interface name="velocity"/>
    </joint>
    <!-- ARM  (position commands)               -->
    <joint name="shoulder_joint">
      <command_interface name="position">
        <param name="min">-1.3</param>
        <param name="max"> 1.57</param>
      </command_interface>
      <state_interface name="position"/>
      <state_interface name="velocity"/>
    </joint>
    <joint name="elbow_joint">
      <command_interface name="position">
        <param name="min">-1.57</param>
        <param name="max"> 0.57</param>
      </command_interface>
      <state_interface name="position"/>
      <state_interface name="velocity"/>
    </joint>
    <joint name="wrist_joint">
      <command_interface name="position">
        <param name="min">0.0</param>
        <param name="max">2.7</param>
      </command_interface>
      <state_interface name="position"/>
      <state_interface name="velocity"/>
    </joint>
    <joint name="wrist_roll_joint">
      <command_interface name="position">
        <param name="min">-1.0</param>
        <param name="max"> 1.0</param>
      </command_interface>
      <state_interface name="position"/>
      <state_interface name="velocity"/>
    </joint>
    <joint name="gripper_left_joint">
      <command_interface name="position">
        <param name="min">0.0</param>
        <param name="max">0.025</param>
      </command_interface>
      <state_interface name="position"/>
      <state_interface name="velocity"/>
    </joint>
  </ros2_control>
  <link name="base_link">
    <!-- Outer shell -->
    <visual>
      <origin rpy="0 0 0" xyz="0 0 0"/>
      <geometry>
        <box size="0.28 0.32 0.105"/>
      </geometry>
      <material name="dark_grey"/>
    </visual>
    <!-- Top plate -->
    <visual>
      <origin rpy="0 0 0" xyz="0 0 0.0485"/>
      <geometry>
        <box size="0.274 0.314 0.006"/>
      </geometry>
      <material name="grey"/>
    </visual>
    <!-- Battery layer -->
    <visual>
      <origin rpy="0 0 0" xyz="0 0 -0.034999999999999996"/>
      <geometry>
        <box size="0.26 0.29000000000000004 0.033"/>
      </geometry>
      <material name="black"/>
    </visual>
    <!-- Motor driver layer -->
    <visual>
      <origin rpy="0 0 0" xyz="-0.04 0 -0.004499999999999997"/>
      <geometry>
        <box size="0.12600000000000003 0.29000000000000004 0.018"/>
      </geometry>
      <material name="dark_grey"/>
    </visual>
    <!-- Power + ESP32 layer -->
    <visual>
      <origin rpy="0 0 0" xyz="0 0 0.015500000000000007"/>
      <geometry>
        <box size="0.26 0.29000000000000004 0.016"/>
      </geometry>
      <material name="dark_grey"/>
    </visual>
    <!-- Raspberry Pi 5 PCB -->
    <visual>
      <origin rpy="0 0 0" xyz="-0.03 0.03 0.0355"/>
      <geometry>
        <box size="0.085 0.056 0.004"/>
      </geometry>
      <material name="green"/>
    </visual>
    <!-- Arm mount boss -->
    <visual>
      <origin rpy="0 0 0" xyz="0.0 0.0 0.0645"/>
      <geometry>
        <cylinder length="0.024" radius="0.032"/>
      </geometry>
      <material name="black"/>
    </visual>
    <collision>
      <origin rpy="0 0 0" xyz="0 0 0"/>
      <geometry>
        <box size="0.28 0.32 0.105"/>
      </geometry>
    </collision>
    <inertial>
      <mass value="3.5"/>
      <origin rpy="0 0 0" xyz="0 0 0"/>
      <inertia ixx="0.03308229166666666" ixy="0" ixz="0" iyy="0.026082291666666663" iyz="0" izz="0.05273333333333333"/>
    </inertial>
  </link>
  <!-- Low friction if the chassis box grazes the ground; high mu here blocks strafing. -->
  <gazebo reference="base_link">
    <collision>
      <surface>
        <friction>
          <ode>
            <mu>0.01</mu>
            <mu2>0.01</mu2>
          </ode>
        </friction>
      </surface>
    </collision>
  </gazebo>
  <gazebo>
    <plugin filename="libgz_ros2_control-system.so" name="gz_ros2_control::GazeboSimROS2ControlPlugin">
      <parameters>config/ros2_controllers.yaml</parameters>
      <robot_param>robot_description</robot_param>
      <robot_param_node>robot_state_publisher</robot_param_node>
    </plugin>
  </gazebo>
  <link name="front_left_wheel_link">
    <visual>
      <origin rpy="1.5707963267948966 0 0" xyz="0 0 0"/>
      <geometry>
        <cylinder length="0.04" radius="0.05"/>
      </geometry>
      <material name="black"/>
    </visual>
    <!-- Hub detail -->
    <visual>
      <origin rpy="1.5707963267948966 0 0" xyz="0 0 0"/>
      <geometry>
        <cylinder length="0.042" radius="0.019000000000000003"/>
      </geometry>
      <material name="grey"/>
    </visual>
    <!-- Sphere contact (gz-sim mecanum demo) — symmetric patch, less arc drift than cylinder -->
    <collision>
      <origin rpy="0 0 0" xyz="0 0 0"/>
      <geometry>
        <sphere radius="0.05"/>
      </geometry>
    </collision>
    <inertial>
      <mass value="0.3"/>
      <origin xyz="0 0 0"/>
      <inertia ixx="0.00030000000000000003" ixy="0" ixz="0" iyy="0.00030000000000000003" iyz="0" izz="0.00030000000000000003"/>
    </inertial>
  </link>
  <joint name="front_left_wheel_joint" type="continuous">
    <parent link="base_link"/>
    <child link="front_left_wheel_link"/>
    <origin rpy="0 0 0" xyz="0.095 0.13 -0.0525"/>
    <axis xyz="0 1 0"/>
    <dynamics damping="0.01" friction="0.01"/>
  </joint>
  <gazebo reference="front_left_wheel_link">
    <collision>
      <surface>
        <friction>
          <ode>
            <mu>1.0</mu>
            <mu2>0.0</mu2>
            <fdir1 gz:expressed_in="base_link">1 -1 0</fdir1>
          </ode>
        </friction>
      </surface>
    </collision>
  </gazebo>
  <link name="front_right_wheel_link">
    <visual>
      <origin rpy="1.5707963267948966 0 0" xyz="0 0 0"/>
      <geometry>
        <cylinder length="0.04" radius="0.05"/>
      </geometry>
      <material name="black"/>
    </visual>
    <!-- Hub detail -->
    <visual>
      <origin rpy="1.5707963267948966 0 0" xyz="0 0 0"/>
      <geometry>
        <cylinder length="0.042" radius="0.019000000000000003"/>
      </geometry>
      <material name="grey"/>
    </visual>
    <!-- Sphere contact (gz-sim mecanum demo) — symmetric patch, less arc drift than cylinder -->
    <collision>
      <origin rpy="0 0 0" xyz="0 0 0"/>
      <geometry>
        <sphere radius="0.05"/>
      </geometry>
    </collision>
    <inertial>
      <mass value="0.3"/>
      <origin xyz="0 0 0"/>
      <inertia ixx="0.00030000000000000003" ixy="0" ixz="0" iyy="0.00030000000000000003" iyz="0" izz="0.00030000000000000003"/>
    </inertial>
  </link>
  <joint name="front_right_wheel_joint" type="continuous">
    <parent link="base_link"/>
    <child link="front_right_wheel_link"/>
    <origin rpy="0 0 0" xyz="0.095 -0.13 -0.0525"/>
    <axis xyz="0 1 0"/>
    <dynamics damping="0.01" friction="0.01"/>
  </joint>
  <gazebo reference="front_right_wheel_link">
    <collision>
      <surface>
        <friction>
          <ode>
            <mu>1.0</mu>
            <mu2>0.0</mu2>
            <fdir1 gz:expressed_in="base_link">1 1 0</fdir1>
          </ode>
        </friction>
      </surface>
    </collision>
  </gazebo>
  <link name="rear_left_wheel_link">
    <visual>
      <origin rpy="1.5707963267948966 0 0" xyz="0 0 0"/>
      <geometry>
        <cylinder length="0.04" radius="0.05"/>
      </geometry>
      <material name="black"/>
    </visual>
    <!-- Hub detail -->
    <visual>
      <origin rpy="1.5707963267948966 0 0" xyz="0 0 0"/>
      <geometry>
        <cylinder length="0.042" radius="0.019000000000000003"/>
      </geometry>
      <material name="grey"/>
    </visual>
    <!-- Sphere contact (gz-sim mecanum demo) — symmetric patch, less arc drift than cylinder -->
    <collision>
      <origin rpy="0 0 0" xyz="0 0 0"/>
      <geometry>
        <sphere radius="0.05"/>
      </geometry>
    </collision>
    <inertial>
      <mass value="0.3"/>
      <origin xyz="0 0 0"/>
      <inertia ixx="0.00030000000000000003" ixy="0" ixz="0" iyy="0.00030000000000000003" iyz="0" izz="0.00030000000000000003"/>
    </inertial>
  </link>
  <joint name="rear_left_wheel_joint" type="continuous">
    <parent link="base_link"/>
    <child link="rear_left_wheel_link"/>
    <origin rpy="0 0 0" xyz="-0.095 0.13 -0.0525"/>
    <axis xyz="0 1 0"/>
    <dynamics damping="0.01" friction="0.01"/>
  </joint>
  <gazebo reference="rear_left_wheel_link">
    <collision>
      <surface>
        <friction>
          <ode>
            <mu>1.0</mu>
            <mu2>0.0</mu2>
            <fdir1 gz:expressed_in="base_link">1 1 0</fdir1>
          </ode>
        </friction>
      </surface>
    </collision>
  </gazebo>
  <link name="rear_right_wheel_link">
    <visual>
      <origin rpy="1.5707963267948966 0 0" xyz="0 0 0"/>
      <geometry>
        <cylinder length="0.04" radius="0.05"/>
      </geometry>
      <material name="black"/>
    </visual>
    <!-- Hub detail -->
    <visual>
      <origin rpy="1.5707963267948966 0 0" xyz="0 0 0"/>
      <geometry>
        <cylinder length="0.042" radius="0.019000000000000003"/>
      </geometry>
      <material name="grey"/>
    </visual>
    <!-- Sphere contact (gz-sim mecanum demo) — symmetric patch, less arc drift than cylinder -->
    <collision>
      <origin rpy="0 0 0" xyz="0 0 0"/>
      <geometry>
        <sphere radius="0.05"/>
      </geometry>
    </collision>
    <inertial>
      <mass value="0.3"/>
      <origin xyz="0 0 0"/>
      <inertia ixx="0.00030000000000000003" ixy="0" ixz="0" iyy="0.00030000000000000003" iyz="0" izz="0.00030000000000000003"/>
    </inertial>
  </link>
  <joint name="rear_right_wheel_joint" type="continuous">
    <parent link="base_link"/>
    <child link="rear_right_wheel_link"/>
    <origin rpy="0 0 0" xyz="-0.095 -0.13 -0.0525"/>
    <axis xyz="0 1 0"/>
    <dynamics damping="0.01" friction="0.01"/>
  </joint>
  <gazebo reference="rear_right_wheel_link">
    <collision>
      <surface>
        <friction>
          <ode>
            <mu>1.0</mu>
            <mu2>0.0</mu2>
            <fdir1 gz:expressed_in="base_link">1 -1 0</fdir1>
          </ode>
        </friction>
      </surface>
    </collision>
  </gazebo>
  <!-- LiDAR mast -->
  <link name="lidar_mast_link">
    <visual>
      <origin rpy="0 0 0" xyz="0 0 0.18"/>
      <geometry>
        <cylinder length="0.36" radius="0.01"/>
      </geometry>
      <material name="dark_grey"/>
    </visual>
    <collision>
      <origin rpy="0 0 0" xyz="0 0 0.18"/>
      <geometry>
        <cylinder length="0.36" radius="0.01"/>
      </geometry>
    </collision>
    <inertial>
      <mass value="0.080"/>
      <origin rpy="0 0 0" xyz="0 0 0.18"/>
      <inertia ixx="0.0008659999999999999" ixy="0" ixz="0" iyy="0.0008659999999999999" iyz="0" izz="4.000000000000001e-06"/>
    </inertial>
  </link>
  <joint name="lidar_mast_joint" type="fixed">
    <parent link="base_link"/>
    <child link="lidar_mast_link"/>
    <origin rpy="0 0 0" xyz="-0.1 0.0 0.0525"/>
  </joint>
  <!-- LiDAR sensor link -->
  <link name="lidar_link">
    <visual>
      <origin rpy="0 0 0" xyz="0 0 0.0205"/>
      <geometry>
        <cylinder length="0.041" radius="0.038"/>
      </geometry>
      <material name="black"/>
    </visual>
    <visual>
      <origin rpy="0 0 0" xyz="0 0 0.05"/>
      <geometry>
        <cylinder length="0.018" radius="0.032"/>
      </geometry>
      <material name="dark_grey"/>
    </visual>
    <visual>
      <origin rpy="0 0 0" xyz="0.034999999999999996 0 0.0205"/>
      <geometry>
        <box size="0.004 0.012 0.0205"/>
      </geometry>
      <material name="blue"/>
    </visual>
    <collision>
      <origin rpy="0 0 0" xyz="0 0 0.0205"/>
      <geometry>
        <cylinder length="0.041" radius="0.038"/>
      </geometry>
    </collision>
    <inertial>
      <mass value="0.185"/>
      <origin rpy="0 0 0" xyz="0 0 0.0205"/>
      <inertia ixx="9.270041666666665e-05" ixy="0" ixz="0" iyy="9.270041666666665e-05" iyz="0" izz="0.00013356999999999998"/>
    </inertial>
  </link>
  <joint name="lidar_joint" type="fixed">
    <parent link="lidar_mast_link"/>
    <child link="lidar_link"/>
    <origin rpy="0 0 0" xyz="0 0 0.36"/>
  </joint>
  <gazebo reference="lidar_link">
    <sensor name="lidar" type="gpu_lidar">
      <topic>scan</topic>
      <update_rate>10</update_rate>
      <lidar>
        <scan>
          <horizontal>
            <samples>360</samples>
            <resolution>1</resolution>
            <min_angle>-3.14159</min_angle>
            <max_angle>3.14159</max_angle>
          </horizontal>
        </scan>
        <range>
          <min>0.12</min>
          <max>12.0</max>
          <resolution>0.01</resolution>
        </range>
        <noise>
          <type>gaussian</type>
          <mean>0.0</mean>
          <stddev>0.01</stddev>
        </noise>
      </lidar>
      <always_on>true</always_on>
      <visualize>false</visualize>
      <gz_frame_id>lidar_link</gz_frame_id>
    </sensor>
  </gazebo>
  <!-- IMU -->
  <link name="imu_link">
    <visual>
      <origin xyz="0 0 0"/>
      <geometry>
        <box size="0.02 0.02 0.02"/>
      </geometry>
      <material name="dark_grey"/>
    </visual>
    <inertial>
      <mass value="0.05"/>
      <origin xyz="0 0 0"/>
      <inertia ixx="0.001" ixy="0" ixz="0" iyy="0.001" iyz="0" izz="0.001"/>
    </inertial>
  </link>
  <joint name="imu_joint" type="fixed">
    <parent link="base_link"/>
    <child link="imu_link"/>
    <origin rpy="0 0 0" xyz="0 0 0.105"/>
  </joint>
  <gazebo reference="imu_link">
    <sensor name="imu" type="imu">
      <topic>imu/data</topic>
      <update_rate>100</update_rate>
      <always_on>true</always_on>
      <imu>
        <angular_velocity>
          <x>
            <noise type="gaussian">
              <mean>0</mean>
              <stddev>0.009</stddev>
            </noise>
          </x>
          <y>
            <noise type="gaussian">
              <mean>0</mean>
              <stddev>0.009</stddev>
            </noise>
          </y>
          <z>
            <noise type="gaussian">
              <mean>0</mean>
              <stddev>0.009</stddev>
            </noise>
          </z>
        </angular_velocity>
        <linear_acceleration>
          <x>
            <noise type="gaussian">
              <mean>0</mean>
              <stddev>0.021</stddev>
            </noise>
          </x>
          <y>
            <noise type="gaussian">
              <mean>0</mean>
              <stddev>0.021</stddev>
            </noise>
          </y>
          <z>
            <noise type="gaussian">
              <mean>0</mean>
              <stddev>0.021</stddev>
            </noise>
          </z>
        </linear_acceleration>
      </imu>
      <gz_frame_id>imu_link</gz_frame_id>
    </sensor>
  </gazebo>
  <!-- Shoulder -->
  <link name="shoulder_link">
    <visual>
      <origin rpy="0 0 0" xyz="0 0 0.0275"/>
      <geometry>
        <cylinder length="0.055" radius="0.02"/>
      </geometry>
      <material name="grey"/>
    </visual>
    <visual>
      <origin rpy="0 0 0" xyz="0 0 0.010"/>
      <geometry>
        <cylinder length="0.020" radius="0.038"/>
      </geometry>
      <material name="dark_grey"/>
    </visual>
    <collision>
      <origin rpy="0 0 0" xyz="0 0 0.0275"/>
      <geometry>
        <cylinder length="0.055" radius="0.02"/>
      </geometry>
    </collision>
    <inertial>
      <mass value="0.3"/>
      <origin rpy="0 0 0" xyz="0 0 0.0275"/>
      <inertia ixx="0.00010562499999999998" ixy="0" ixz="0" iyy="0.00010562499999999998" iyz="0" izz="6e-05"/>
    </inertial>
  </link>
  <joint name="shoulder_joint" type="revolute">
    <parent link="base_link"/>
    <child link="shoulder_link"/>
    <origin rpy="0 0 0" xyz="0 0 0.0765"/>
    <axis xyz="0 1 0"/>
    <limit effort="5.0" lower="-1.3" upper="1.57" velocity="0.10"/>
    <dynamics damping="0.08" friction="0.10"/>
  </joint>
  <!-- Upper arm -->
  <link name="upper_arm_link">
    <visual>
      <origin rpy="0 1.5707963267948966 0" xyz="0.075 0 0"/>
      <geometry>
        <cylinder length="0.15" radius="0.018"/>
      </geometry>
      <material name="grey"/>
    </visual>
    <visual>
      <origin rpy="0 1.5707963267948966 0" xyz="0.15 0 0"/>
      <geometry>
        <cylinder length="0.018" radius="0.030599999999999995"/>
      </geometry>
      <material name="dark_grey"/>
    </visual>
    <collision>
      <origin rpy="0 1.5707963267948966 0" xyz="0.075 0 0"/>
      <geometry>
        <cylinder length="0.15" radius="0.018"/>
      </geometry>
    </collision>
    <inertial>
      <mass value="0.24"/>
      <origin rpy="0 0 0" xyz="0.075 0 0"/>
      <inertia ixx="3.887999999999999e-05" ixy="0" ixz="0" iyy="0.00046943999999999995" iyz="0" izz="0.00046943999999999995"/>
    </inertial>
  </link>
  <joint name="elbow_joint" type="revolute">
    <parent link="shoulder_link"/>
    <child link="upper_arm_link"/>
    <origin rpy="0 0 0" xyz="0 0 0.055"/>
    <axis xyz="0 1 0"/>
    <limit effort="5.0" lower="-1.57" upper="0.57" velocity="0.10"/>
    <dynamics damping="0.06" friction="0.08"/>
  </joint>
  <!-- Forearm -->
  <link name="forearm_link">
    <visual>
      <origin rpy="0 1.5707963267948966 0" xyz="0.06 0 0"/>
      <geometry>
        <cylinder length="0.12" radius="0.015"/>
      </geometry>
      <material name="grey"/>
    </visual>
    <visual>
      <origin rpy="0 1.5707963267948966 0" xyz="0.12 0 0"/>
      <geometry>
        <cylinder length="0.015" radius="0.024"/>
      </geometry>
      <material name="dark_grey"/>
    </visual>
    <collision>
      <origin rpy="0 1.5707963267948966 0" xyz="0.06 0 0"/>
      <geometry>
        <cylinder length="0.12" radius="0.015"/>
      </geometry>
    </collision>
    <inertial>
      <mass value="0.18"/>
      <origin rpy="0 0 0" xyz="0.06 0 0"/>
      <inertia ixx="2.0249999999999998e-05" ixy="0" ixz="0" iyy="0.00022612499999999998" iyz="0" izz="0.00022612499999999998"/>
    </inertial>
  </link>
  <joint name="wrist_joint" type="revolute">
    <parent link="upper_arm_link"/>
    <child link="forearm_link"/>
    <origin rpy="0 0 0" xyz="0.15 0 0"/>
    <axis xyz="0 1 0"/>
    <limit effort="5.0" lower="0.0" upper="2.7" velocity="0.10"/>
    <dynamics damping="0.04" friction="0.06"/>
  </joint>
  <!-- Hand -->
  <link name="hand_link">
    <visual>
      <origin rpy="0 1.5707963267948966 0" xyz="0.0275 0 0"/>
      <geometry>
        <cylinder length="0.055" radius="0.012"/>
      </geometry>
      <material name="grey"/>
    </visual>
    <collision>
      <origin rpy="0 1.5707963267948966 0" xyz="0.0275 0 0"/>
      <geometry>
        <cylinder length="0.055" radius="0.012"/>
      </geometry>
    </collision>
    <inertial>
      <mass value="0.1"/>
      <origin rpy="0 0 0" xyz="0.0275 0 0"/>
      <inertia ixx="7.2000000000000005e-06" ixy="0" ixz="0" iyy="2.8808333333333333e-05" iyz="0" izz="2.8808333333333333e-05"/>
    </inertial>
  </link>
  <joint name="wrist_roll_joint" type="revolute">
    <parent link="forearm_link"/>
    <child link="hand_link"/>
    <origin rpy="0 0 0" xyz="0.12 0 0"/>
    <axis xyz="1 0 0"/>
    <limit effort="5.0" lower="-1.0" upper="1.0" velocity="0.10"/>
    <dynamics damping="0.02" friction="0.03"/>
  </joint>
  <!-- Gripper base -->
  <link name="gripper_base_link">
    <visual>
      <origin rpy="0 1.5707963267948966 0" xyz="0.018 0 0"/>
      <geometry>
        <box size="0.028 0.052 0.018"/>
      </geometry>
      <material name="dark_grey"/>
    </visual>
    <collision>
      <origin rpy="0 1.5707963267948966 0" xyz="0.018 0 0"/>
      <geometry>
        <box size="0.028 0.052 0.018"/>
      </geometry>
    </collision>
    <inertial>
      <mass value="0.06"/>
      <origin rpy="0 0 0" xyz="0.018 0 0"/>
      <inertia ixx="1.5139999999999997e-05" ixy="0" ixz="0" iyy="5.5399999999999995e-06" iyz="0" izz="1.7439999999999996e-05"/>
    </inertial>
  </link>
  <joint name="gripper_base_joint" type="fixed">
    <parent link="hand_link"/>
    <child link="gripper_base_link"/>
    <origin rpy="0 0 0" xyz="0.055 0 0"/>
  </joint>
  <!-- Left gripper finger — ACTIVE joint, commanded by gripper_controller -->
  <link name="gripper_left_link">
    <visual>
      <origin rpy="0 1.5707963267948966 0" xyz="0.022 0 0"/>
      <geometry>
        <box size="0.044 0.009 0.014"/>
      </geometry>
      <material name="grey"/>
    </visual>
    <collision>
      <origin rpy="0 1.5707963267948966 0" xyz="0.022 0 0"/>
      <geometry>
        <box size="0.044 0.009 0.014"/>
      </geometry>
    </collision>
    <inertial>
      <mass value="0.03"/>
      <origin rpy="0 0 0" xyz="0.022 0 0"/>
      <inertia ixx="6.924999999999999e-07" ixy="0" ixz="0" iyy="5.329999999999999e-06" iyz="0" izz="5.042499999999999e-06"/>
    </inertial>
  </link>
  <joint name="gripper_left_joint" type="prismatic">
    <parent link="gripper_base_link"/>
    <child link="gripper_left_link"/>
    <origin rpy="0 0 0" xyz="0 0.022 0"/>
    <axis xyz="0 1 0"/>
    <limit effort="5.0" lower="0.0" upper="0.025" velocity="0.10"/>
    <dynamics damping="0.01" friction="0.01"/>
  </joint>
  <link name="gripper_right_link">
    <visual>
      <origin rpy="0 1.5707963267948966 0" xyz="0.022 0 0"/>
      <geometry>
        <box size="0.044 0.009 0.014"/>
      </geometry>
      <material name="grey"/>
    </visual>
    <collision>
      <origin rpy="0 1.5707963267948966 0" xyz="0.022 0 0"/>
      <geometry>
        <box size="0.044 0.009 0.014"/>
      </geometry>
    </collision>
    <inertial>
      <mass value="0.03"/>
      <origin rpy="0 0 0" xyz="0.022 0 0"/>
      <inertia ixx="6.924999999999999e-07" ixy="0" ixz="0" iyy="5.329999999999999e-06" iyz="0" izz="5.042499999999999e-06"/>
    </inertial>
  </link>
  <joint name="gripper_right_joint" type="prismatic">
    <parent link="gripper_base_link"/>
    <child link="gripper_right_link"/>
    <origin rpy="0 0 0" xyz="0 -0.022 0"/>
    <axis xyz="0 1 0"/>
    <limit effort="5.0" lower="-0.025" upper="0.0" velocity="0.10"/>
    <dynamics damping="0.01" friction="0.01"/>
    <mimic joint="gripper_left_joint" multiplier="-1" offset="0"/>
  </joint>
  <!-- TCP frame -->
  <link name="tcp_link"/>
  <joint name="tcp_joint" type="fixed">
    <parent link="gripper_base_link"/>
    <child link="tcp_link"/>
    <origin rpy="0 0 0" xyz="0.050 0 0"/>
  </joint>
</robot>
