<?xml version="1.0" ?>
<!-- =================================================================================== -->
<!-- |    This document was autogenerated by xacro from orion.xacro                    | -->
<!-- |    EDITING THIS FILE BY HAND IS NOT RECOMMENDED                                 | -->
<!-- =================================================================================== -->
<robot name="orion">
  <!-- ================= BASE ================= -->
  <link name="base_link">
    <visual>
      <geometry>
        <box size="0.3 0.2 0.1"/>
      </geometry>
    </visual>
    <collision>
      <geometry>
        <box size="0.3 0.2 0.1"/>
      </geometry>
    </collision>
    <inertial>
      <mass value="2.0"/>
      <origin xyz="0 0 0"/>
      <inertia ixx="0.02" ixy="0.0" ixz="0.0" iyy="0.02" iyz="0.0" izz="0.02"/>
    </inertial>
  </link>
  <link name="left_wheel">
    <visual>
      <geometry>
        <cylinder length="0.02" radius="0.05"/>
      </geometry>
      <origin rpy="1.57 0 0"/>
    </visual>
    <inertial>
      <mass value="0.5"/>
      <origin xyz="0 0 0"/>
      <inertia ixx="0.001" ixy="0.0" ixz="0.0" iyy="0.001" iyz="0.0" izz="0.0005"/>
    </inertial>
  </link>
  <joint name="left_wheel_joint" type="continuous">
    <parent link="base_link"/>
    <child link="left_wheel"/>
    <origin xyz="0 0.1 -0.05"/>
    <axis xyz="0 1 0"/>
  </joint>
  <link name="right_wheel">
    <visual>
      <geometry>
        <cylinder length="0.02" radius="0.05"/>
      </geometry>
      <origin rpy="1.57 0 0"/>
    </visual>
    <inertial>
      <mass value="0.5"/>
      <origin xyz="0 0 0"/>
      <inertia ixx="0.001" ixy="0.0" ixz="0.0" iyy="0.001" iyz="0.0" izz="0.0005"/>
    </inertial>
  </link>
  <joint name="right_wheel_joint" type="continuous">
    <parent link="base_link"/>
    <child link="right_wheel"/>
    <origin xyz="0 -0.1 -0.05"/>
    <axis xyz="0 1 0"/>
  </joint>
  <!-- ================= CASTER ================= -->
  <link name="caster">
    <visual>
      <geometry>
        <sphere radius="0.03"/>
      </geometry>
    </visual>
  </link>
  <joint name="caster_joint" type="fixed">
    <parent link="base_link"/>
    <child link="caster"/>
    <origin xyz="-0.1 0 -0.05"/>
  </joint>
  <!-- ================= SHOULDER ================= -->
  <link name="shoulder_link">
    <visual>
      <geometry>
        <box size="0.05 0.05 0.05"/>
      </geometry>
    </visual>
    <inertial>
      <mass value="0.3"/>
      <origin xyz="0 0 0"/>
      <inertia ixx="0.000125" ixy="0.0" ixz="0.0" iyy="0.000125" iyz="0.0" izz="0.000125"/>
    </inertial>
  </link>
  <joint name="shoulder_joint" type="revolute">
    <parent link="base_link"/>
    <child link="shoulder_link"/>
    <origin xyz="0 0 0.1"/>
    <axis xyz="0 0 1"/>
  </joint>
  <!-- ================= ARM LINK 1 ================= -->
  <link name="link1">
    <visual>
      <geometry>
        <cylinder length="0.2" radius="0.02"/>
      </geometry>
      <origin rpy="0 1.57 0"/>
    </visual>
    <inertial>
      <mass value="1.0"/>
      <origin xyz="0 0 0"/>
      <inertia ixx="0.0034" ixy="0.0" ixz="0.0" iyy="0.0034" iyz="0.0" izz="0.0002"/>
    </inertial>
  </link>
  <joint name="joint1" type="revolute">
    <parent link="shoulder_link"/>
    <child link="link1"/>
    <origin xyz="0 0 0.05"/>
    <axis xyz="0 1 0"/>
  </joint>
  <!-- ================= ARM LINK 2 ================= -->
  <link name="link2">
    <visual>
      <geometry>
        <cylinder length="0.2" radius="0.02"/>
      </geometry>
      <origin rpy="0 1.57 0"/>
    </visual>
    <inertial>
      <mass value="0.8"/>
      <origin xyz="0 0 0"/>
      <inertia ixx="0.0027" ixy="0.0" ixz="0.0" iyy="0.0027" iyz="0.0" izz="0.00016"/>
    </inertial>
  </link>
  <joint name="joint2" type="revolute">
    <parent link="link1"/>
    <child link="link2"/>
    <origin xyz="0 0 0.2"/>
    <axis xyz="0 1 0"/>
  </joint>
  <!-- ================= SENSORS ================= -->
  <!-- LiDAR -->
  <link name="lidar_link">
    <visual>
      <geometry>
        <cylinder length="0.05" radius="0.03"/>
      </geometry>
    </visual>
  </link>
  <joint name="lidar_joint" type="fixed">
    <parent link="base_link"/>
    <child link="lidar_link"/>
    <origin xyz="0.1 0 0.15"/>
  </joint>
  <!-- IMU -->
  <link name="imu_link"/>
  <joint name="imu_joint" type="fixed">
    <parent link="base_link"/>
    <child link="imu_link"/>
    <origin xyz="0 0 0.1"/>
  </joint>
  <!-- Camera -->
  <link name="camera_link">
    <visual>
      <geometry>
        <box size="0.03 0.03 0.03"/>
      </geometry>
    </visual>
  </link>
  <joint name="camera_joint" type="fixed">
    <parent link="base_link"/>
    <child link="camera_link"/>
    <origin xyz="0.15 0 0.2"/>
  </joint>
  <!-- ================= ROS2 CONTROL ================= -->
  <ros2_control name="orion_system" type="system">
    <hardware>
      <plugin>gazebo_ros2_control/GazeboSystem</plugin>
    </hardware>
    <joint name="left_wheel_joint">
      <command_interface name="velocity"/>
      <state_interface name="velocity"/>
      <state_interface name="position"/>
    </joint>
    <joint name="right_wheel_joint">
      <command_interface name="velocity"/>
      <state_interface name="velocity"/>
      <state_interface name="position"/>
    </joint>
    <joint name="shoulder_joint">
      <command_interface name="position"/>
      <state_interface name="position"/>
    </joint>
    <joint name="joint1">
      <command_interface name="position"/>
      <state_interface name="position"/>
    </joint>
    <joint name="joint2">
      <command_interface name="position"/>
      <state_interface name="position"/>
    </joint>
  </ros2_control>
</robot>
