<?xml version="1.0"?>
<robot xmlns:xacro="http://www.ros.org/wiki/xacro">

  <xacro:property name="wheel_radius" value="0.05"/>
  <xacro:property name="wheel_width"  value="0.04"/>
  <xacro:property name="wheel_mass"   value="0.3"/>
  <xacro:property name="base_z"       value="0.105"/>
  <xacro:property name="wheel_x_off"  value="0.095"/>
  <xacro:property name="wheel_y_off"  value="0.13"/>
  <xacro:property name="wheel_z_off"  value="${-base_z/2.0}"/>

  <xacro:macro name="mecanum_wheel" params="name x_sign y_sign fdir1_y">
    <link name="${name}_wheel_link">
      <visual>
        <origin xyz="0 0 0" rpy="${pi/2} 0 0"/>
        <geometry><cylinder radius="${wheel_radius}" length="${wheel_width}"/></geometry>
        <material name="black"/>
      </visual>
      <visual>
        <origin xyz="0 0 0" rpy="${pi/2} 0 0"/>
        <geometry><cylinder radius="${wheel_radius*0.38}" length="${wheel_width+0.002}"/></geometry>
        <material name="grey"/>
      </visual>
      <collision>
        <origin xyz="0 0 0" rpy="${pi/2} 0 0"/>
        <geometry><cylinder radius="${wheel_radius}" length="${wheel_width}"/></geometry>
      </collision>
      <inertial>
        <mass value="${wheel_mass}"/>
        <origin xyz="0 0 0"/>
        <inertia
          ixx="${(1.0/12.0)*wheel_mass*(3*wheel_radius*wheel_radius+wheel_width*wheel_width)}"
          iyy="${0.5*wheel_mass*wheel_radius*wheel_radius}"
          izz="${(1.0/12.0)*wheel_mass*(3*wheel_radius*wheel_radius+wheel_width*wheel_width)}"
          ixy="0" ixz="0" iyz="0"/>
      </inertial>
    </link>

    <joint name="${name}_wheel_joint" type="continuous">
      <parent link="base_link"/>
      <child  link="${name}_wheel_link"/>
      <origin xyz="${x_sign*wheel_x_off} ${y_sign*wheel_y_off} ${wheel_z_off}" rpy="0 0 0"/>
      <axis xyz="0 1 0"/>
      <dynamics damping="0.01" friction="0.01"/>
    </joint>

  </xacro:macro>

  <xacro:macro name="wheels">
    <xacro:mecanum_wheel name="front_left"  x_sign="1"  y_sign="1"  fdir1_y="-0.7071"/>
    <xacro:mecanum_wheel name="front_right" x_sign="1"  y_sign="-1" fdir1_y="0.7071"/>
    <xacro:mecanum_wheel name="rear_left"   x_sign="-1" y_sign="1"  fdir1_y="0.7071"/>
    <xacro:mecanum_wheel name="rear_right"  x_sign="-1" y_sign="-1" fdir1_y="-0.7071"/>

  </xacro:macro>

</robot>
